Workbook

Sheet Summary (short)
A1: Foundation | B1: Engineering | C1: Product and Process | D1: Advisory and Business Consulting | E1: Leadership and Strategy
A2: Digital & AI Terminology, AI Concepts, Tool overviews | B2: AI Systems and Architecture | C2: AI-Augmented Requirement Engineering | D2: AI & Automation Use Case Spotting | E2: Managing AI Transformations
A3: Data Literacy | B3: Agentic Software Development | C3: AI-Enhanced User Research | D3: AI Cost & Value Economics | E3: AI Workforce Strategy
A4: Personal AI Productivity | B4: AI-Driven Testing & QA | D4: Consultative Prompting | E4: Decision Making with AI
A5: Corporate Ethics & Compliance | B5: AI-Supported Code Modernization | D5: AI Ecosystem Knowledge
B6: AI-Assisted Documentation
B7: Sustainable Software & Green Coding
B15: Parellele Entwicklung | C15: Schulungsempfehlungen | D15: Wer hält den Betrieb?
A16: ASE Empfehlung: | B16: basierend auf dem Score kannst du einen Lernpfad durchlaufen, der | C16: ASE -> Literacy -> anonymes Self Assessment aus der HTML von unserer ASE externen Seite (kein Betriebsrat)

Sheet Summary (long)
A1: Roles (Brainstorming Vanessa), Target Groups
B4: Group 1 | C4: Group 2 | D4: Roles
B5: All Employees | C5: Consultants | D5: Business & Strategy Consulting | F5: Idee MLM: Als Portfolio (?)
D8: Products & Value Streams
D9: Technology Consulting
E10: Technical Engineering
E11: SW-Engineering & Architecture
D12: Application Management
E13: Service Technology
E14: Service Mgmt
D15: Project Management & Agility
E16: Project Mgmt
E17: Agility
C18: Corporate Function
D19: Support
D20: Finance
D21: HR
D22: Legal
C23: Leadership
D24: LHIND Business Manager
D25: LHIND Top Management
B28: Foundation: General Literacy | C28: Engineering Literacy | D28: Product and Process Literacy | E28: Advisory and Biz Literacy | F28: Leadership and Strategy
B29: Digital & AI Terminology, AI Concepts, Tool overviews | C29: AI Systems and Architecture | D29: AI-Augmented Requirements | E29: AI & Automation Use Case Spotting | F29: Managing AI Transformations
B30: Data Literacy & Interpretation, Critical Evaluation | C30: Agentic Software Development | D30: AI-Enhanced User Research | E30: AI Cost & Value Economics | F30: AI Workforce Strategy
B31: Digital Ethics & Compliance | C31: AI-Driven Testing & QA | E31: Consultative Prompting | F31: Decision Making with AI
B32: Personal AI Productivity | C32: AI-Supported Code Modernization | E32: AI Ecosystem Knowledge
C33: AI-Assisted Documentation

Sheet Capability
A1: AI-Literacy | B1: ID | C1: Cluster | D1: Title | E1: Full Title | F1: Description | G1: Basic | H1: Advanced | I1: Expert | J1: What is it? Why is it relevant? | K1: Business & Strategy Consulting | L1: Products & Value Streams | M1: Technology Consulting | N1: Application Management | O1: Project Management & Agility | P1: Corporate Functions | Q1: Leadership | S1: All Roles | T1: Business & Strategy Consulting | U1: Products & Value Streams | V1: Technology Consulting | W1: Application Management | X1: Project Management & Agility | Y1: Corporate Functions | Z1: Leadership
A2: 1 | B2: 1 | C2: Foundation | D2: Digital & AI Terminology, AI Concepts, Tool overviews | E2: =_xlfn.CONCAT(C2, " - ", D2) -> Foundation - Digital & AI Terminology, AI Concepts, Tool overviews | F2: This competency establishes a shared understanding of core AI and digital concepts across the organization. It includes familiarity with key terminology, distinctions between major AI approaches (e.g., Machine Learning, Deep Learning, Generative AI), basic data foundations, and awareness of commonly used AI tools and platforms. The goal is to enable everyone at LHIND to communicate clearly and credibly with clients, colleagues, and technical teams, avoiding hype-driven discussions and unrealistic expectations. A consistent conceptual grounding helps teams identify appropriate use cases, explain AI capabilities and limitations accurately, and translate technical topics into business-relevant conversations. | G2: The employee possesses a foundational literacy, ensuring they can navigate corporate communications and internal announcements without ambiguity. Taxonomic Accuracy: Correctly distinguishes and defines core concepts, understanding the hierarchical relationship (e.g., Deep Learning, Machine Learning). Vocabulary: Utilizes the corporate glossary to define standard terms (e.g., Supervised vs. Unsupervised Learning, Tokens, Hallucinations) and identifies the basic functions of approved internal AI tools. Data Awareness: Recognizes the importance of data quality in internal systems and understands the "Garbage In, Garbage Out" principle regarding company data. Tool Overview: Knows the basic, available AI tools at LHIND and understands their purpose and usages Outcome: Can actively participate in departmental meetings where AI initiatives are discussed; understands the company’s tech strategy without confusion. | H2: The employee understands the semi-formal logic of the concepts and can map business problems within their specific function (e.g., HR, Finance, Ops) to technological categories. Conceptual Mapping: Identifies which class of algorithm/method is appropriate for specific operational pain points (e.g., using Regression for forecasting sales vs. LLMs for drafting internal docs). Tool Selection: Has an overview of the common tools, tool landscape and knows the major players. Evaluates and selects appropriate tools for their team's workflows, understanding the trade-offs between speed, cost, and accuracy. Data Dependency: Understands specific data requirements (volume, privacy, compliance) for models relevant to their department and anticipates potential bias in automated decisions. Outcome: Can lead credible discussions with IT/Tech departments or vendors; writes accurate requirements for digital projects; avoids requesting infeasible AI magic for routine problems. | I2: The employee acts as a bridge between business strategy and technology, capable of guiding organizational investment and governance. Critical Evaluation: Analyzes the theoretical limitations of AI architectures to prevent the deployment of fragile systems in critical business processes (e.g., understanding why GenAI is risky for precise financial calculations). Strategic Guidance: Understands and interprets market trends, vendor claims, and emerging tech realistically Strategic Architecture: Designs or oversees comprehensive workflows, assessing the long-term ROI, maintenance costs, and scalability of AI integration within their business unit. Standardization & Governance: Actively refines the internal glossary, mentors team members to correct misconceptions, and ensures the department remains resilient against external vendor hype. Outcome: Acts as a trusted advisor to Senior Leadership on digital transformation; validates the business case and technical soundness of major internal investments. | J2: What: Konzepte (ML, DL, GenAI), Glossar, Datengrundlage, Tool basics Why: Gemeinsame Sprache in der Org, Credible client conversations, avoids hype/misuse | K2: Advanced | L2: Advanced | M2: Expert | N2: Advanced | O2: Advanced | P2: Advanced | Q2: Advanced | S2: Basic What Is Copilot? An Overview of Microsoft’s AI Tools: https://www.linkedin.com/learning/what-is-copilot-an-overview-of-microsoft-s-ai-tools/use-copilot-on-the-web-in-windows-or-the-mobile-app Everyday AI Business Tools: https://www.linkedin.com/learning/everyday-ai-business-tools/exploring-essential-ai-tools-for-eveyday-business Agentic AI: A Framework for Planning and Execution https://www.linkedin.com/learning/agentic-ai-a-framework-for-planning-and-execution/introduction-to-agentic-ai-avoiding-the-hype Advanced Comparing AI Research Tools: ChatGPT, Claude, Gemini, and Perplexity https://www.linkedin.com/learning/comparing-ai-research-tools-chatgpt-claude-gemini-and-perplexity/choosing-the-right-ai-tool-for-the-job | T2: Basic Learning AI for Business Analysis: https://www.linkedin.com/learning/learning-ai-for-business-analysis/transform-your-business-analysis-career
A3: 1 | B3: 2 | C3: Foundation | D3: Data Literacy | E3: =_xlfn.CONCAT(C3, " - ", D3) -> Foundation - Data Literacy | F3: This competency defines the capacity to read, analyze, and argue with data, transforming raw metrics into evidence-based decisions. It also covers tool usage and the responsibilities and mindset regarding data quality, including the own role and responsibilities in maintaining a high quality data landscape. It includes reading reports and dashboards accurately, understanding basic statistical concepts, recognizing data limitations, and questioning and critically evaluate how data is collected, analyzed, and presented. Employees must demonstrate the ability to identify common logical fallacies, such as conflating correlation with causation, and recognize the limitations of specific datasets, including selection bias and sampling errors. The goal is to foster a data-driven culture where decisions are informed by evidence, assumptions are questioned constructively, and both internal and client discussions are grounded in realistic interpretation of data. | G3: The employee effectively consumes standard reports and understands fundamental statistical concepts necessary for daily operations. Descriptive Statistics: Correctly interprets and understands basic statistical concepts such as mean, median, mode and spread (range), distinguishing between them in reporting. Visual Literacy: Accurately reads standard organizational charts (bar, line, pie) and dashboards without misinterpreting the scale or axes. Data Hygiene: Adheres to basic data entry standards to ensure integrity and understands the direct impact data quality on reports or AI. Tools Usage: Understands how and when to use common LHIND tools (Excel, PowerBI, Data Entry tools) to retrieve and explore information Outcome: Can independently monitor KPIs and operational metrics; understands the "what" of the data presented in team meetings. | H3: The employee actively analyzes data to find patterns and questions the validity of the information presented. Statistical Reasoning: Understands concepts of distribution and variance; distinguishes between simple correlation and causality. Critical Scrutiny: Identifies misleading visualizations (e.g., truncated axes, cherry-picked timeframes) and questions the context of the data (e.g., "Is the sample size n sufficient?"). Contextualization: Connects disparate data points to form a coherent narrative, identifying outliers or anomalies that require investigation rather than dismissal. Understands data requirements for analytics and AI initiatives Tools Usage: Uses advanced features of BI/Analytics tools or AI assisted analysis Outcome: Detects flaws in proposals based on weak data; asks "Why?" and "How was this measured?" during presentations; prevents teams from acting on statistical noise. | I3: The employee evaluates the methodology behind data generation and enforces high standards of epistemic rigor. Methodological Critique: scrutinizes the data collection process itself, identifying systemic biases (e.g., survivorship bias, selection bias) that invalidate the dataset. Probabilistic Thinking: Evaluates risks and forecasts using probabilistic frameworks (e.g., confidence intervals, scenarios) rather than demanding deterministic certainty. Data Strategy: Defines the metrics that should be measured to track strategic goals, ensuring they do not create perverse incentives (Goodhart’s Law). Advises on data tool selection, architecture, and integration with AI systems Outcome: Sets the standard for truth within the department; acts as a gatekeeper against "vanity metrics"; ensures major strategic decisions are backed by statistically sound evidence. | J3: What: Datenarten, Bias, Korrelation vs Kausalität, Understand Data Importance, output validation, source checking Why: Evidenzbasierte Arbeit, realistic expectations. | K3: Expert | L3: Expert | M3: Expert | N3: Advanced | O3: Advanced | P3: Advanced | Q3: Advanced | S3: Basic Data-Backed Decision Making https://www.linkedin.com/learning/data-backed-decision-making/making-better-decisions
A4: 1 | B4: 3 | C4: Foundation | D4: Personal AI Productivity | E4: =_xlfn.CONCAT(C4, " - ", D4) -> Foundation - Personal AI Productivity | F4: This competency defines the individual’s ability to leverage AI tools to improve personal output, optimize time management, and streamline cognitive workflows. It moves beyond mere tool awareness and to the application of Large Language Models (LLMs) and automation software for drafting, summarizing, coding, or problem-solving (among others). It includes effective prompting, iterative refinement of AI-generated content (Human in the loop), responsible handling of sensitive information, and thoughtful judgment about when AI support is appropriate. Crucially, this competency includes the judgment to discern when to use AI versus manual effort, preventing the "time-sink" of over-engineering simple tasks. The objective is to transform the employee from a passive user into an "AI-augmented professional," capable of delivering higher-value work by offloading routine cognitive load to digital assistants while maintaining full accountability for the final quality. | G4: The employee uses AI as a "better search engine" or basic drafter for standalone tasks. Prompting Basics: Formulates simple, zero-shot queries (e.g., "Draft an email to X about Y") but may accept generic outputs without much refinement. Task Application: Uses approved tools for low-risk summarization of long documents or to brainstorm initial ideas for projects. Is aware of applications and use cases in everyday work Validation: Manually reviews AI output for hallucinations or factual errors before using it, treating the AI as a junior intern whose work needs checking. Outcome: Saves time on administrative drafting and reading; reduces the "blank page" problem. | H4: The employee engages in "Chain-of-Thought" reasoning with the AI, integrating it deeply into complex workflows. Advanced Prompting: Uses techniques like "Few-Shot Prompting" (providing examples) and role-setting (e.g., "Act as a Senior Financial Analyst...") to guide the AI toward specific formats and tones. Iterative Refinement: Does not settle for the first result; engages in a multi-turn dialogue to refine, critique, and polish the output. Context Management: Knows how to safely feed relevant context (anonymized data, project background) into the tool to get highly specific, actionable results. Outcome: Produces higher quality work faster; uses AI to critique their own logic or simulate counter-arguments before meetings. | I4: The employee builds personal systems and custom tools that automate repetitive cognitive loops Customization: Configures "Custom Instructions" or builds personal "GPTs/Agents" pre-loaded with specific project knowledge, style guides, and formatting rules. Workflow Chaining: Connects AI tools with other software (e.g., using scripts or integrations) to automate multi-step processes (e.g., "Summarize meeting notes -> extract action items -> draft Jira tickets"). Prompt Library: Maintains and shares a library of high-efficacy prompts for the team, effectively acting as a productivity multiplier for others. Outcome: Operates at a significantly higher velocity than peers; eliminates administrative drudgery entirely; creates reusable assets that benefit the wider team. | J4: What: GenAI für Emails, Kalender, Summaries, M365, Async Work, Collab-Tools. Why: Individuelle Effizienzsteigerung, Effizienz in verteilten Teams. | K4: Expert | L4: Expert | M4: Expert | N4: Basic | O4: Expert | P4: Advanced | Q4: Expert
A5: 1 | B5: 4 | C5: Foundation | D5: Corporate Ethics & Compliance | E5: =_xlfn.CONCAT(C5, " - ", D5) -> Foundation - Corporate Ethics & Compliance | F5: This competency defines the moral, legal, and ethical guardrails for responsible digital and AI usage within the organization. It requires a solid understanding of regulatory frameworks (e.g., GDPR, EU AI Act) and internal compliance rules, combined with the ability to identify and mitigate ethical risks such as bias, lack of transparency, misuse of data, or automation errors. Beyond knowing what is legally permitted, employees act with intention and accountability, carefully considering impacts on people, the organization, and society—especially in ambiguous or complex situations. Technical feasibility alone is not sufficient; decisions must balance innovation with fairness, dignity, and long‑term trust. Mastery of this competency strengthens stakeholder confidence, reduces legal and reputational risks, and safeguards the organization’s license to operate in a highly regulated environment. | G5: The employee acts with fundamental sensitivity, focusing on compliance and adherence to established guidelines. Compliance: Deploys technology, data, and AI in strict accordance with applicable guidelines and regulations. Guardrail Awareness: Knows and respects relevant legal, corporate-specific, and cultural boundaries. Risk Reflection: Reflects on obvious risks and impacts on users and stakeholders (e.g., "Is this data sensitive?"). Consultation: Actively seeks guidance and consultation in cases of uncertainty rather than making assumptions. Outcome: Acts responsibly within their own area of tasks; demonstrates basic ethical sensitivity and rule-conforming behavior | H5: The employee engages in context-aware weighing of options and assumes proactive responsibility for outcomes. Impact Evaluation: Systematically assesses the effects of technology deployment on people, the organization, and society. Risk Detection: Proactively identifies potential risks regarding bias, data privacy, or fairness within workflows or models. Ethical Decision Making: Makes ethically reflected decisions even when faced with conflicting goals (e.g., balancing Speed vs. Fairness). Advocacy: Actively brings ethical aspects into project planning and discussions; promotes the transparent and responsible use of data and AI. Outcome: Acts reflectively and assumes responsibility beyond their immediate role; prevents ethical debt. | I5: The employee exercises systemic responsibility, shaping standards that build long-term trust. Strategic Anticipation: Anticipates the long-term societal and organizational implications of technological decisions. Governance Design: Develops and establishes ethical guidelines, standards, or governance models for the organization. Balanced Strategy: Strategically balances the triangle of Innovation, Economic Viability, and Responsibility. Cultural Leadership: Fosters a culture of integrity, transparency, and sustainability; acts as a role model for responsible technology use. Outcome: actively designs responsible value creation chains; strengthens organizational trust and "Social License to Operate." + protects the brand's ethical reputation against systemic failures (aus 3). | K5: Advanced | L5: Advanced | M5: Expert | N5: Expert | O5: Advanced | P5: Advanced | Q5: Expert
A6: 1 | B6: 5 | C6: Engineering | D6: AI Systems and Architecture | E6: =_xlfn.CONCAT(C6, " - ", D6) -> Engineering - AI Systems and Architecture | F6: This competency defines the technical fluency required to understand how AI solutions are architected, integrated, and deployed within an enterprise environment. It moves beyond the theoretical understanding of algorithms to the practical reality of systems engineering. This includes a grasp of the end-to-end data pipeline—from ingestion and pre-processing to model training (or fine-tuning) and final inference. Employees must understand critical architectural concepts such as APIs, cloud vs. on-premise infrastructure, latency requirements, and the distinct roles of components like Vector Databases or Orchestration layers. The goal is to demystify the "Black Box" of AI, enabling employees to assess technical feasibility, anticipate integration challenges with legacy systems, and make informed decisions regarding "Build vs. Buy." This literacy ensures that projects are scoped realistically, with a clear understanding of the computational resources and maintenance overhead required for production-grade systems. | G6: The employee can identify the major building blocks of an AI system and understands standard technical vocabulary. Vocabulary: Correctly defines terms like "API" (Application Programming Interface), "Inference" (running the model), "Latency" (speed), and "Cloud Computing." System Boundaries: Recognizes that an AI model is not a standalone app but a component that must talk to other systems (e.g., "The Chatbot needs to read the SharePoint database"). Resource Awareness: Understands that AI processes consume computing power (GPU/CPU) and that this translates directly to operational costs. Outcome: Can follow technical updates from IT; understands why a "simple change" might require significant backend work. | H6: The employee understands how data moves through the system and the dependencies between different components. Pipeline Logic: Maps the flow of information: $Input -> Preprocessing -> Model -> Postprocessing -> Output. Understands where errors can occur at each stage. Integration Constraints: Identifies potential bottlenecks (e.g., "If the API is slow, the user waits") and data privacy boundaries (e.g., "Does data leave our secure cloud environment?"). Lifecycle Awareness: Recognizes that deploying a model is just the beginning; understands the need for monitoring and updates (MLOps concepts). Outcome: Can scope projects effectively; identifies missing technical prerequisites (e.g., "We can't use this AI tool because we don't have an API for that data source"). | I6: The employee evaluates technical designs against business goals, optimizing for cost, performance, and reliability. Trade-off Analysis: Balances conflicting constraints, such as Accuracy vs. Latency or Cost vs. Privacy. Makes decisions on "Edge AI" (running on device) vs. "Cloud AI." Scalability: Assesses whether a proposed architecture can handle 10 users or 10,000 users, identifying single points of failure. Technical Debt: Critiques architectural choices that solve an immediate problem but create long-term maintenance burdens (e.g., hard-coding rules instead of using a flexible model). Outcome: Validates vendor technical proposals; challenges IT on over-engineered or under-resourced solutions; ensures the "Total Cost of Ownership" (TCO) is understood before build begins. | J6: What: Models vs Apps, RAG, system components, model lifecycle awareness, frameworks, orchestraction tools, AI Services Why: Defining solutions, realistic thinking, Solution architecture | K6: n. a. | L6: Basic | M6: Expert | N6: n. a. | O6: n. a. | P6: n. a. | Q6: n. a. | S6: Basic Agentic AI for Developers: Concepts and Application for Enterprises https://www.linkedin.com/learning/agentic-ai-for-developers-concepts-and-application-for-enterprises/building-your-own-ai-agent Advanced Agentic AI Fundamentals: Architectures, Frameworks, and Applications https://www.linkedin.com/learning/agentic-ai-fundamentals-architectures-frameworks-and-applications/agentic-ai-the-future-of-smart-ai-is-here
A7: 1 | B7: 6 | C7: Engineering | D7: Agentic Software Development | E7: =_xlfn.CONCAT(C7, " - ", D7) -> Engineering - Agentic Software Development | F7: This competency defines the paradigm shift from "writing code" to "orchestrating development." It entails the ability to effectively utilize autonomous AI agents to execute engineering tasks—ranging from scaffolding new features to refactoring legacy modules. The core skill is no longer syntax memorization, but Intent Specification: the ability to clearly articulate technical requirements and constraints (context) that an agent can execute. Crucially, this requires a rigorous Verification Mindset—the ability to review, audit, and debug machine-generated code with the same scrutiny applied to a junior human developer. It involves managing the "Context Window" (knowing which files to feed the agent) and guiding the agent through iterative error correction. The objective is to elevate the developer from a "typist" to an "Architect," where the human focuses on system design, security, and business logic, while the agent handles implementation details and boilerplate. | G7: The developer uses agents to accelerate isolated, well-defined coding tasks. Scoped Prompting: Can delegate single-file tasks to an agent (e.g., "Write a unit test for this function," "Refactor this method to be async"). Code Review: Reads every line of agent-generated code to ensure it actually runs and follows basic style guidelines before committing. Hallucination Check: Recognizes when an agent invents a library or method that doesn't exist and manually corrects it. Outcome: Eliminates boilerplate work; speeds up unit testing and documentation; maintains code quality in individual files. | H7: The developer guides an agent through multi-step, multi-file changes to implement complete features. Context Engineering: Curates the correct set of files, documentation, and types to feed the agent so it "understands" the broader system architecture before coding. Iterative Steering: Engages in a dialogue with the agent to refine behavior (e.g., "That solution broke the login flow; try again using the AuthService class"). Debugging Agent Logic: Identifies why an agent failed (e.g., "It didn't see the interface definition") and provides the missing information rather than rewriting the code manually. Outcome: Delivers full features faster; effectively uses agents to refactor code across multiple dependencies; reduces "context switching" fatigue. | I7: The developer treats the agent as a "Senior Pair Programmer," using it for high-level design and complex migrations. Architectural Prompts: Asks the agent to propose high-level designs or folder structures before writing code, validating the approach against system constraints. Large-Scale Refactoring: Orchestrates agents to perform tedious, system-wide changes (e.g., "Migrate all API calls from REST to GraphQL") while managing the risk of regression. Security Auditing: specifically prompts agents to audit their own code for vulnerabilities (e.g., "Review your last output for SQL injection risks") and verifies the findings. Outcome: Acts as a "Technical Lead" for an AI workforce; builds prototypes in hours, not days; maintains high architectural integrity despite the speed of generation. | J7: What: Nutzung von (Git) Copilot, Cursor, Ghostwriter, Probabilistisch vs Deterministisch, Logik Why: Entwickler-Produktivität, | K7: Basic | L7: Basic | M7: Expert | N7: Basic | O7: n. a. | P7: n. a. | Q7: n. a. | S7: Basic Agentic AI Fundamentals: Architectures, Frameworks, and Applications https://www.linkedin.com/learning/agentic-ai-for-developers-concepts-and-application-for-enterprises/building-your-own-ai-agent AI and Developer Productivity https://www.linkedin.com/learning/ai-and-developer-productivity/ai-and-developer-productivity The AI Ecosystem for Developers: Models, Datasets, and APIs https://www.linkedin.com/learning/the-ai-ecosystem-for-developers-models-datasets-and-apis/getting-started-with-the-ai-ecosystem
A8: 1 | B8: 7 | C8: Engineering | D8: AI-Driven Testing & QA | E8: =_xlfn.CONCAT(C8, " - ", D8) -> Engineering - AI-Driven Testing & QA | F8: This competency defines the strategic application of AI to the quality assurance process, marking a shift from manual verification to intelligent, automated validation. It moves beyond traditional "scripted" testing (where humans write every step) to understanding how AI tools can autonomously generate test cases, detect anomalies, and "self-heal" broken tests when software updates occur. For employees, this literacy involves recognizing that AI is a force multiplier for speed and coverage, not a magic wand that eliminates the need for human oversight. It requires distinguishing between deterministic checks (is A + B = C?) and probabilistic AI validation (does this look right?). The objective is to transition the organization from reactive "bug catching" to proactive "quality engineering", where AI predicts risk areas and optimizes testing scope, ensuring faster release cycles without compromising stability or compliance. | G8: The employee understands the vocabulary of modern QA and the fundamental difference between manual and AI-assisted testing. Core Concepts: Distinguishes between Manual Testing, Traditional Automation (scripts), and AI-Driven Testing (autonomous). Vocabulary: Correctly uses terms like "Regression Testing" (checking old features still work), "False Positives" (AI flagging a bug that isn't real), and "Test Coverage." Limitations: Recognizes that AI cannot validate "Business Intent" (e.g., the software works technically, but does it solve the user's problem?). Outcome: Can discuss project timelines realistically, understanding that "AI Testing" still requires setup and review time; does not expect zero bugs immediately. | H8: The employee identifies where to apply AI tools to optimize the testing process and reduce bottlenecks. Strategic Application: Identifies high-value use cases for AI, such as "Visual Regression" (spotting UI changes) or "Test Data Generation" (creating fake user data for privacy compliance). Self-Healing Awareness: Understands the value of "Self-Healing" tests (AI that fixes the script when a button name changes) in reducing maintenance costs. Shift Left: Advocates for testing earlier in the development cycle ("Shift Left"), using AI to scan requirements or code drafts before the product is fully built. Outcome: Prioritizes testing resources effectively; evaluates tool vendors based on "maintenance effort" rather than just "creation speed"; writes clear acceptance criteria that AI can validate. | I8: The employee designs the comprehensive Quality Strategy, balancing speed, cost, and risk in an AI-native environment. Risk-Based Testing: Uses AI metrics to predict which parts of the software are most likely to fail (based on code changes) and focuses testing efforts there. Data Governance: Manages the complex compliance issues of "Test Data Management" (TDM), ensuring AI doesn't train on or expose sensitive PII during testing. Algorithmic Integrity: Audits the AI testing tools themselves to ensure they aren't "hallucinating" success (passing a broken feature) or creating "Flaky Tests" (random failures). Outcome: transform the QA function from a cost center to a speed enabler; defines the organization's "Definition of Done"; ensures reliability in continuous delivery pipelines. | J8: What: Test-Genierung, Synthetische Daten. Why: Code-Qualität und Speed. | K8: n. a. | L8: Basic | M8: Expert | N8: Advanced | O8: n. a. | P8: n. a. | Q8: n. a. | S8: Basic Advanced AI-Powered Software Development: Coding, Testing, and System Design https://www.linkedin.com/learning/ai-powered-software-development-coding-testing-and-system-design/code-generation-and-completion-what-are-my-options
A9: 1 | B9: 8 | C9: Engineering | D9: AI-Supported Code Modernization | E9: =_xlfn.CONCAT(C9, " - ", D9) -> Engineering - AI-Supported Code Modernization | F9: This competency defines the strategic ability to leverage AI for transforming legacy systems into modern, maintainable, and secure software. It moves beyond the concept of "rewriting code" to understanding how AI accelerates the refactoring process—translating outdated languages (e.g., COBOL to Java), updating libraries, and documenting "Black Box" systems where original developers have long since left. For employees, this means grasping that "Modernization" is not just a technical upgrade but a risk reduction strategy. It involves recognizing that AI tools can analyze vast codebases to map dependencies, identify security vulnerabilities, and generate test cases for behavior that was previously undocumented. The objective is to enable the organization to pay down "Technical Debt" efficiently, ensuring that critical business operations are not reliant on fragile, obsolete technology. | G9: The employee understands the business risks of legacy code and the basic role AI plays in mitigating them. Vocabulary: Correctly defines terms like "Technical Debt" (cost of rework), "Refactoring" (improving structure without changing function), and "Legacy Code" (old, valuable, but hard to change). AI Role: Recognizes that AI helps assist developers in understanding old code, not just magically rewriting it perfectly. Documentation: values the ability of AI to generate documentation for undocumented systems, reducing the "Key Person Risk" (what happens if the expert leaves?). Outcome: Can articulate the business case for modernization projects; understands why "keeping the lights on" costs increase over time. | H9: The employee actively manages the modernization process, ensuring AI outputs are validated and risks are controlled. Conversion Logic: Understands the difference between a direct "Line-by-Line" translation (often bad) and "Idiomatic Refactoring" (writing code the way a modern developer would). Testing Necessity: Insists on rigorous regression testing; realizes that if the old code had a bug, the AI might faithfully copy that bug into the new language. Scope Management: Identifies which parts of a system are "High Risk/Low Value" (candidates for retirement) vs. "High Risk/High Value" (candidates for AI modernization). Outcome: Drafts realistic project roadmaps; allocates time for "Human Review" of AI-generated code; prioritizes modules for modernization based on business criticality. | I9: The employee orchestrates large-scale systemic changes, balancing architectural purity with business continuity. Architectural Decoupling: Strategies how to break a "Monolith" (one giant program) into "Microservices" using AI to identify logical seams and boundaries. Pattern Recognition: Uses AI to scan the entire codebase for recurring anti-patterns or security flaws, applying fixes at scale rather than one by one. Vendor & Tool Governance: Evaluates the efficacy of specific modernization agents/tools; ensures that proprietary code isn't leaking into public models during the refactoring process. Outcome: Leads the "Strangler Fig" strategy (gradually replacing the old system); quantifies the ROI of modernization (e.g., "We reduced deployment time by 50%"); safeguards the organization's intellectual property. | J9: What: Code-Erklärung, Refactoring mit KI, z.B. für Legacy Systeme. Why: Modernisierung beschleunigen. | K9: Basic | L9: Basic | M9: Expert | N9: Expert | O9: n. a. | P9: n. a. | Q9: n. a.
A10: 1 | B10: 9 | C10: Engineering | D10: AI-Assisted Documentation | E10: =_xlfn.CONCAT(C10, " - ", D10) -> Engineering - AI-Assisted Documentation | F10: This competency defines the ability to leverage AI to solve one of the most persistent challenges in any organization: the "Knowledge Silo." It moves beyond simply writing reports to understanding how AI can dynamically generate, update, and query technical documentation from the underlying systems (code, databases, workflows). For non-engineers, this means the ability to use AI tools to "interrogate" a system and extract plain-language explanations of how it functions ("Reverse Engineering" business rules). It also encompasses the strategy of "Documentation as Living Knowledge"—ensuring that as software or processes change, the corresponding documentation is updated automatically or semi-automatically. The objective is to reduce "Key Person Risk" (where knowledge lives only in one person's head) and ensure that business decisions are based on how the systems actually work, not how they were described three years ago. | G10: The employee knows that documentation can be generated on-demand and how to query it. Retrieval Literacy: Instead of saying "I can't find the manual," the employee uses AI search tools ("Chat with your Data") to find answers within technical repositories. Concept Awareness: Understands that "Code Comments" and "Readme files" exist and that AI can translate these into business-readable summaries. Staleness Detection: Recognizes that if the AI is reading a file from 2021, the answer is likely wrong ("Hallucination by Outdated Context"). Outcome: Can independently answer basic functional questions about internal tools without emailing the engineering team. | H10: The employee actively uses AI to bridge the gap between technical reality and business process. Business Logic Extraction: Uses AI to read code snippets or technical specs and extract the actual business rules (e.g., "According to the code, the discount is applied before tax, not after"). Gap Analysis: Compares the AI-generated description of the system against the official SOPs to find discrepancies ("The system does X, but our policy says Y"). Drafting Assistance: Uses AI to draft technical requirements or bug reports that engineers can actually use, minimizing back-and-forth. Outcome: Acts as a translator between IT and Business; ensures that process maps reflect technical reality; reduces "requirements churn." | I10: The employee treats documentation as a strategic asset and enforces systems to keep it alive. Knowledge Architecture: Designs the flow of information, ensuring that AI tools have access to the "Single Source of Truth" and are blocked from reading deprecated drafts. Docs-as-Code Strategy: Champions the engineering practice where documentation is treated like software (versioned, reviewed, and automated), ensuring business continuity. Legacy Archeology: Leads initiatives to document "Black Box" legacy systems using AI, effectively recovering lost institutional knowledge before a crisis occurs. Outcome: Mitigation of "Bus Factor" (risk of losing key staff); audits and approves the information architecture; ensures the organization remains compliant and auditable. | J10: What: Auto-Docu, Tech-Writing mit KI. Why: Wartbarkeit und Wissenstransfer. | K10: Advanced | L10: Advanced | M10: Expert | N10: Expert | O10: n. a. | P10: Advanced | Q10: Basic
A11: 1 | B11: 10 | C11: Engineering | D11: Sustainable Software & Green Coding | E11: =_xlfn.CONCAT(C11, " - ", D11) -> Engineering - Sustainable Software & Green Coding | F11: This competency defines the practice of designing, building, and maintaining software that is energy-efficient by default. It moves beyond high-level operational metrics (GreenOps) to the granular level of Green Coding—understanding how specific algorithms, languages, and architectural patterns directly dictate physical energy consumption. It requires a semi-formal understanding of "Energy Proportionality" (ensuring systems consume energy only when delivering value) and the ability to optimize code not just for speed, but for carbon intensity. The competency encompasses efficient data handling (minimizing payload sizes), resource-aware logic (avoiding "polling" loops), and the selection of hardware-accelerated libraries. The strategic objective is to embed sustainability as a core "Non-Functional Requirement" alongside security and scalability, ensuring that development teams minimize the carbon footprint of their code before it ever reaches production. | G11: The developer understands the physical connection between code execution and energy consumption. Carbon Literacy: Correctly defines the relationship between software intensity and hardware power draw (Energy = Power x Time). Bloat Recognition: Identifies "Zombie Resources" (unused containers/VMs) and inefficient data practices (e.g., retrieving all columns in a SQL query when only one is needed). Principles: Adheres to the basic tenets of the Green Software Foundation, such as "Carbon Efficiency" (least amount of carbon possible) and "Hardware Efficiency" (using the least amount of embodied carbon). Outcome: Avoids obvious waste; writes clean, concise code that doesn't unnecessarily tax the CPU or memory. | H11: The developer actively profiles and refactors code to reduce computational cost and energy usage. Algorithmic Efficiency: Evaluates code complexity (Big O notation) to select algorithms that minimize CPU cycles (e.g., choosing O(n log n) sorting over O(n^2)), directly reducing energy burn. Data Minimization: Optimizes network payloads (compression, efficient formats like Parquet vs. CSV) to reduce data transfer energy. Resource Management: Implements "Sleep" states and efficient event-driven patterns (e.g., Webhooks) instead of continuous polling loops that keep processors active. Outcome: Delivers software that is leaner and faster; identifies "hot spots" in the code that are disproportionately energy-intensive and refactors them. | I11: The developer architects systems that dynamically adapt to energy availability and grid intensity. Carbon-Aware Computing: Designs systems capable of "Temporal Shifting" (running heavy batch jobs only when the grid is green/renewable) and "Spatial Shifting" (routing workloads to data centers in cooler climates or greener grids). Architectural Efficiency: Makes strategic trade-offs between Microservices (flexibility) and Monoliths (efficiency), recognizing that the network overhead of microservices can increase total energy cost. Measurement & Telemetry: Builds "Software Carbon Intensity" (SCI) metrics directly into the CI/CD pipeline, enabling the team to fail a build if the carbon footprint exceeds a defined threshold. Outcome: Builds "Net Zero" ready systems; sets the standard for sustainable engineering practices; creates feedback loops where energy efficiency drives architectural innovation. | J11: What: Energie-Footprint von KI/Cloud, Efficiency considerations Why: ESG-Ziele der Kunden | K11: Advanced | L11: Advanced | M11: Advanced | N11: Basic | O11: n. a. | P11: n. a. | Q11: Basic | S11: Basic DevOps Best Practices for Sustainability in the Cloud https://www.linkedin.com/learning/devops-best-practices-for-sustainability-in-the-cloud/sustainable-practices-for-growth-and-impact-in-devops
A12: 1 | B12: 11 | C12: Product and Process | D12: AI-Augmented Requirement Engineering | E12: =_xlfn.CONCAT(C12, " - ", D12) -> Product and Process - AI-Augmented Requirement Engineering | F12: This competency defines the strategic integration of AI into the product definition lifecycle, transforming how business needs are captured, analyzed, and translated into technical specifications. It entails leveraging Natural Language Processing (NLP) tools to assist in eliciting, structuring, and refining requirements, ensuring they are unambiguous, consistent, and testable. Employees must understand how to use AI to synthesize unstructured inputs (e.g., meeting transcripts, emails) into formal artifacts like User Stories, Use Cases, or Gherkin syntax (Given -> When -> Then). Crucially, it involves a rigorous "Human-in-the-Loop" validation process to detect logical gaps or "hallucinated" features that the AI might introduce. The objective is to reduce the "Cone of Uncertainty" early in the project, minimizing costly rework caused by misunderstood requirements and ensuring a precise alignment between business intent and engineering execution. | G12: The employee uses AI to speed up the writing of standard requirement documents and ensure basic clarity. Drafting: Generates initial drafts of User Stories or functional requirements from rough bullet points (e.g., "Turn these notes into a standard JIRA ticket format"). Standardization: Uses AI to enforce a consistent tone and structure across documents, ensuring all requirements follow the "INVEST" criteria (Independent, Negotiable, Valuable, Estimable, Small, Testable). Summarization: Rapidly condenses long stakeholder interview transcripts into key feature requests and pain points. Outcome: Reduces administrative overhead; ensures that tickets and docs are legible and follow the company template. | H12: The employee uses AI to interrogate requirements, finding edge cases and logical inconsistencies before developers see them including AI-Augmented Behavior-Driven Development (BDD), where AI generates Given/When/Then scenarios from natural language requirements. Ambiguity Detection: prompts the AI to act as a "Critical Reviewer," specifically asking it to identify vague terms (e.g., "fast," "user-friendly") that need quantification (e.g., "< 200ms"). Scenario Generation: Uses AI to brainstorm "Edge Cases" and "Unhappy Paths" (e.g., "What happens if the user loses internet connection mid-transaction?") that were missed in the initial scope. Translation: Converts textual requirements into structured formats like Mermaid.js code for diagrams or Gherkin syntax for automated testing.Leverages AI to generate BDD scenarios (Given/When/Then) directly from stakeholder conversations, enabling automated acceptance testing from Day 1. Outcome: Delivers robust, "developer-ready" specifications; proactively identifies gaps in logic; reduces the back-and-forth between Business and IT. | I12: The employee manages the entire requirements ecosystem, ensuring that changes propagate correctly and align with high-level goals. Impact Analysis: Uses AI to trace the downstream impact of a requirement change (e.g., "If we change this login rule, which 5 other modules break?"). Conflict Resolution: Analyzes large sets of requirements from different stakeholders to identify conflicting constraints (e.g., Stakeholder A wants Speed, Stakeholder B wants complex Encryption). Living Specifications: Maintains a dynamic, AI-updated specification repository where requirements auto-sync with code changes, API contracts, and test results – eliminating the 'Rotting Spec' problem entirely. Outcome: Ensures complete traceability from "Business Goal" to "Code Deployment"; manages scope creep effectively using data; aligns product roadmap with technical reality. | J12: What: User Stories & Akzeptanzkriterien via KI. Why: Bessere Spezifikationen, schneller. | K12: Expert | L12: Expert | M12: Advanced | N12: Basic | O12: Basic | P12: Basic | Q12: Basic
A13: 1 | B13: 12 | C13: Product and Process | D13: AI-Enhanced User Research | E13: =_xlfn.CONCAT(C13, " - ", D13) -> Product and Process - AI-Enhanced User Research | F13: This competency defines the capability to leverage AI to accelerate the discovery and synthesis of user insights, transforming raw feedback into actionable product strategy. It moves beyond manual data coding to utilizing Natural Language Processing (NLP) for analyzing vast quantities of qualitative data—such as customer interviews, support tickets, and open-ended survey responses—at scale. Employees must understand how to use AI to identify sentiment, extract recurring themes, and even simulate user reactions via "Synthetic Personas" (while strictly maintaining a clear distinction between real and synthetic data). Crucially, this literacy includes the ability to audit AI-generated insights for bias and hallucination, ensuring that speed does not compromise empathy or accuracy. The objective is to democratize access to user insights, allowing teams to make evidence-based decisions faster and reducing the "Time to Insight" from weeks to hours. A strict ethical boundary must be maintained: synthetic data may inform hypotheses but never replace real user validation for high-stakes decisions. | G13: The employee uses AI to process individual data points faster, reducing the manual drudgery of research. Transcription & Summary: Routinely uses AI tools to transcribe meetings and generate accurate, bulleted summaries of customer interviews immediately after they occur. Sentiment Check: Applies basic sentiment analysis tools to gauge the general "mood" of a batch of feedback (Positive/Negative/Neutral). Searchability: Uses AI-enabled repositories to ask questions of existing research (e.g., "What did customers say about the login button last month?") rather than re-running studies. Outcome: Drastically reduces administrative time; ensures no interview or feedback is "lost" in a folder; democratizes access to basic customer sentiments. | H13: The employee uses AI to connect dots across multiple sources, identifying patterns that humans might miss. Thematic Coding: Uses AI to analyze hundreds of open-ended responses and auto-categorize them into specific themes (e.g., "Pricing," "Usability," "Feature Gap"). Cross-Reference: Prompts AI to look for correlations between disparate datasets (e.g., "Do users who complain about speed also mention the mobile app?"). Voice of Customer Analytics: Uses AI to continuously analyze NPS verbatims, support tickets, and review data to surface emerging themes and churn signals at scale. Gap Analysis: Asks the AI to critique the research plan or interview guide, identifying leading questions or missing demographic perspectives before data collection begins. Outcome: Delivers deeper insights faster; uncovers "Long Tail" issues that manual analysis would ignore; validates hypotheses with broad data support. | I13: The employee uses AI to simulate user behaviors and create continuous, automated research loops. Synthetic Personas: Creates and interacts with "Synthetic Users" (AI modeled on real user data) to test early value propositions or messaging before recruiting human participants. Predictive Insight: Uses AI to forecast future user needs or churn risks based on subtle shifts in language patterns across support channels over time. Bias Auditing: Rigorously tests the AI models themselves for cultural or cognitive bias, ensuring that the "Voice of the Customer" isn't skewed by the training data. Establishes clear governance rules for synthetic persona usage: mandatory labeling of synthetic vs. real data, prohibition of synthetic data in regulatory submissions, and regular validation against real user panels. Outcome: Reduces the risk of product flops by "pre-testing" concepts; creates a "Continuous Discovery" engine that runs 24/7; advises leadership on the ethical limits of synthetic data. | J13: What: Sentiment Analyse, Persona Simulation. Why: Tieferes Kundenverständnis. | K13: Expert | L13: Expert | M13: Basic | N13: n. a. | O13: Basic | P13: Basic | Q13: Basic | S13: Basic Active Listening: The Secret to Effective Communication - What is user research? https://www.linkedin.com/learning/active-listening-the-secret-to-effective-communication/what-is-user-research
A14: 1 | B14: 13 | C14: Advisory and Business Consulting | D14: AI & Automation Use Case Spotting | E14: =_xlfn.CONCAT(C14, " - ", D14) -> Advisory and Business Consulting - AI & Automation Use Case Spotting | F14: This competency defines the strategic ability to identify, qualify, and articulate high-value opportunities for AI and automation within business operations. It requires a diagnostic mindset to deconstruct workflows, pinpoint inefficiencies, and map specific technological solutions to genuine business problems. Employees must move beyond "solutioneering" (finding a problem for a cool tool) to a rigorous assessment of Process Suitability, distinguishing between tasks suitable for deterministic automation (RPA) versus those requiring probabilistic reasoning. It involves applying frameworks like the "Impact vs. Feasibility" matrix to prioritize initiatives based on data availability, risk, and potential ROI. The objective is to foster a culture of "Citizen Innovation," where employees actively reduce operational friction by deploying technology to solve specific bottlenecks—reducing manual toil, accelerating analysis, or scaling personalization—ultimately driving measurable business value. | G14: The employee can spot repetitive, low-value tasks in their immediate environment that are ripe for automation. Pain Point Recognition: Identifies tasks that are "Dull, Dirty, or Dangerous" (in a data sense)—specifically manual data entry, copy-pasting between apps, or scheduling. Taxonomy of Waste: Distinguishes between "Cognitive Load" (thinking) and "Administrative Load" (formatting), recognizing that AI is best suited to reduce the latter first. Problem articulation: Can clearly state the problem (Current State) and the desired outcome (Future State) without necessarily knowing the technical "How." Outcome: Generates a backlog of simple "Quick Win" ideas; stops accepting manual drudgery as "just the way things are." | H14: The employee evaluates the feasibility of an idea, ensuring it is technically viable and economically sensible. Feasibility Check: Asks critical questions before proposing a solution: "Do we have the data?", "Is the process stable?", "Is the error tolerance zero?" (if yes, GenAI might be wrong). Tool Matching: Correctly maps the problem to the solution class: Uses RPA for structured, rule-based tasks (e.g., invoicing) and LLMs for unstructured, creative tasks (e.g., summarizing emails). ROI Estimation: Calculates a rough "Return on Investment" based on hours saved (Hours x Rate) vs. the cost of building/buying the tool. Outcome: Submits high-quality project briefs; filters out "Cool but Useless" ideas; prevents the team from automating broken processes ("Paving the Cow Path"). | I14: The employee looks at the entire value chain to transform how work gets done, rather than just speeding up existing steps. Process Re-engineering: Instead of automating step 3 of a 5-step process, they ask: "If we have AI, do we even need steps 2 and 4?" (e.g., changing "Draft -> Review -> Send" to "Auto-Generate -> Approve"). Portfolio Management: Balances a mix of "Horizon 1" (Incremental efficiency) and "Horizon 2" (Transformative) use cases, managing the aggregate risk and reward. Buy vs. Build Strategy: Makes informed decisions on whether to use off-the-shelf SaaS features or commission custom development based on competitive advantage. Outcome: Drives departmental transformation; reallocates headcount from admin tasks to strategic roles; aligns automation efforts with high-level corporate OKRs. | J14: What: Value vs Hype erkennen beim Kunden, RPA, KI Potentiale erkennen Why: Sales & Consulting Erfolg. | K14: Expert | L14: Advanced | M14: Advanced | N14: Basic | O14: Expert | P14: Basic | Q14: Advanced | S14: Basic Agentic AI for Business Analysis https://www.linkedin.com/learning/agentic-ai-for-business-analysis/why-ai-solutions-need-business-analysis-too
A15: 1 | B15: 14 | C15: Advisory and Business Consulting | D15: AI Cost & Value Economics | E15: =_xlfn.CONCAT(C15, " - ", D15) -> Advisory and Business Consulting - AI Cost & Value Economics | F15: This competency defines the financial acumen required to evaluate Artificial Intelligence not just as a technology, but as an economic engine with distinct cost structures and value drivers. It moves beyond the hype of "productivity" to the rigorous analysis of Unit Economics—understanding the direct cost per transaction (e.g., cost per query, token, or generated image) versus the marginal value created. Employees must grasp the concept of Total Cost of Ownership (TCO) for AI, which includes "invisible" costs like cloud inference, vector storage, continuous monitoring, and human review time, often dwarfing the initial licensing fees. The objective is to empower the organization to avoid "Bill Shock" from unmanaged consumption and to make data-driven decisions on whether a use case is financially viable (Value > Cost), ensuring that AI initiatives drive genuine profitability rather than becoming expensive technical novelties. For consulting, this also includes the ability to design AI pricing models for clients – translating technical cost structures into commercial offerings (per-query pricing, outcome-based models, subscription tiers). | G15: The employee understands that AI usage incurs variable costs and tracks consumption against budget. Cost Drivers: Recognizes that "Asking the AI" is not free; understands the difference between fixed costs (seat licenses) and variable costs (usage/tokens). Vocabulary: Correctly defines terms like "Tokens" (parts of words used for billing), "Inference Cost" (running the model), and "Credits." Budget Tracking: Monitors team usage to ensure they stay within the allocated monthly limits; flags unexpected spikes in consumption immediately. Outcome: Prevents "Zombie Subscriptions" (paying for unused tools); encourages responsible usage among team members. | H15: The employee calculates the specific return on investment for individual use cases. Unit Calculation: Estimates the cost of a single operation (e.g., "Summarizing this 50-page PDF costs approx. $0.30 in tokens"). Value Comparison: Compares the AI cost against the alternative (Human Labor Cost); determines if the efficiency gain justifies the expense (e.g., "Is it worth $0.10 to save 2 minutes of employee time?"). Model Selection: Chooses the most cost-effective model for the task—using a cheaper, faster model (e.g., GPT-3.5/Haiku) for simple sorting, and reserving the expensive "Smart" model (e.g., GPT-4/Opus) only for complex reasoning. Applies cost-performance optimization: selects models not just by capability but by cost-per-task ratio (e.g., routing simple classification to Haiku/Flash while reserving Opus/GPT-4 for complex reasoning). Understands GPU inference cost drivers. Outcome: Justifies budget requests with math; kills "Negative ROI" projects early; optimizes workflows to reduce waste. | I15: The employee manages the economic architecture of the organization's AI portfolio. AI FinOps: Implements governance policies to dynamically manage cloud spend (e.g., "Rate Limiting," "Budget Alarms," "Chargebacks" to specific departments). Build vs. Buy: Conducts sophisticated financial modeling to decide whether to rent a model (API cost) or fine-tune/host an open-source model internally (Infrastructure + Maintenance cost). AI Pricing Design: Architects commercial pricing models for AI-powered services (per-transaction, tiered SLAs, outcome-based), ensuring margin protection while remaining competitive. Understands the economics of 'AI as a Service' vs. 'AI-embedded in Consulting'. CAPEX vs. OPEX: Structures AI investments to align with corporate financial goals (e.g., treating GPU clusters as Capital Expenditure vs. API costs as Operational Expenditure). Outcome: Maximizes the organization's "AI Yield"; negotiates enterprise agreements with vendors; ensures the company’s AI strategy is financially sustainable at scale. | J15: What: Token-Kosten, ROI, TCO von KI, Business Cases berechnen Why: Wirtschaftlichkeit bewerten. | K15: Expert | L15: Advanced | M15: Advanced | N15: Basic | O15: Advanced | P15: Basic | Q15: Expert
